Before try

Within TRY block, before g() call
1
2
about to raise exception in g()
Cought exception 12, and thats it...
After catch
