Before try

Within TRY block, before g() call
1
2
about to raise exception in g()
Cought exception 11, and thats it...
   Try block within the catch statement:
about to raise exception in g()
   cought exception 11 in the inner try/catch block,
   with the message:
   "divison by 0 in g()"
After catch
